<?xml version="1.0" encoding="UTF-8"?>
<!-- Generated by org.testng.reporters.JUnitReportReporter -->
<testsuite hostname="LAPTOP-ML4CRSNC" failures="0" tests="2" name="testCases.TC_002_LoginTest" time="180.412" errors="1" timestamp="2024-12-10T17:54:09 IST" skipped="1">
  <testcase classname="testCases.TC_002_LoginTest" name="verify_login" time="0.000">
    <skipped/>
  </testcase> <!-- verify_login -->
  <testcase classname="testCases.TC_002_LoginTest" name="setup" time="180.412">
    <error message="Could not start a new session. Possible causes are invalid address of the remote server or browser start-up failure. 
Host info: host: &#039;LAPTOP-ML4CRSNC&#039;, ip: &#039;192.168.1.4&#039;" type="org.openqa.selenium.SessionNotCreatedException">
      <![CDATA[org.openqa.selenium.SessionNotCreatedException: Could not start a new session. Possible causes are invalid address of the remote server or browser start-up failure. 
Host info: host: 'LAPTOP-ML4CRSNC', ip: '192.168.1.4'
at org.openqa.selenium.remote.RemoteWebDriver.execute(RemoteWebDriver.java:563)
at org.openqa.selenium.remote.RemoteWebDriver.startSession(RemoteWebDriver.java:245)
at org.openqa.selenium.remote.RemoteWebDriver.<init>(RemoteWebDriver.java:174)
at org.openqa.selenium.remote.RemoteWebDriver.<init>(RemoteWebDriver.java:152)
at testCases.BaseClass.setup(BaseClass.java:79)
at java.base/jdk.internal.reflect.DirectMethodHandleAccessor.invoke(DirectMethodHandleAccessor.java:103)
at java.base/java.lang.reflect.Method.invoke(Method.java:580)
at org.testng.internal.invokers.MethodInvocationHelper.invokeMethod(MethodInvocationHelper.java:139)
at org.testng.internal.invokers.MethodInvocationHelper.invokeMethodConsideringTimeout(MethodInvocationHelper.java:69)
at org.testng.internal.invokers.ConfigInvoker.invokeConfigurationMethod(ConfigInvoker.java:390)
at org.testng.internal.invokers.ConfigInvoker.invokeConfigurations(ConfigInvoker.java:325)
at org.testng.internal.invokers.TestMethodWorker.invokeBeforeClassMethods(TestMethodWorker.java:180)
at org.testng.internal.invokers.TestMethodWorker.run(TestMethodWorker.java:122)
at java.base/java.util.ArrayList.forEach(ArrayList.java:1596)
at org.testng.TestRunner.privateRun(TestRunner.java:848)
at org.testng.TestRunner.run(TestRunner.java:621)
at org.testng.SuiteRunner.runTest(SuiteRunner.java:443)
at org.testng.SuiteRunner.runSequentially(SuiteRunner.java:437)
at org.testng.SuiteRunner.privateRun(SuiteRunner.java:397)
at org.testng.SuiteRunner.run(SuiteRunner.java:336)
at org.testng.SuiteRunnerWorker.runSuite(SuiteRunnerWorker.java:52)
at org.testng.SuiteRunnerWorker.run(SuiteRunnerWorker.java:95)
at org.testng.TestNG.runSuitesSequentially(TestNG.java:1280)
at org.testng.TestNG.runSuitesLocally(TestNG.java:1200)
at org.testng.TestNG.runSuites(TestNG.java:1114)
at org.testng.TestNG.run(TestNG.java:1082)
at org.testng.remote.AbstractRemoteTestNG.run(AbstractRemoteTestNG.java:115)
at org.testng.remote.RemoteTestNG.initAndRun(RemoteTestNG.java:293)
at org.testng.remote.RemoteTestNG.main(RemoteTestNG.java:91)
Caused by: org.openqa.selenium.TimeoutException: java.util.concurrent.TimeoutException
Build info: version: '4.27.0', revision: 'd6e718d134'
System info: os.name: 'Windows 10', os.arch: 'amd64', os.version: '10.0', java.version: '21.0.5'
Driver info: driver.version: RemoteWebDriver
at org.openqa.selenium.remote.http.jdk.JdkHttpClient.execute(JdkHttpClient.java:423)
at org.openqa.selenium.remote.tracing.TracedHttpClient.execute(TracedHttpClient.java:54)
at org.openqa.selenium.remote.ProtocolHandshake.createSession(ProtocolHandshake.java:89)
at org.openqa.selenium.remote.ProtocolHandshake.createSession(ProtocolHandshake.java:75)
at org.openqa.selenium.remote.ProtocolHandshake.createSession(ProtocolHandshake.java:61)
at org.openqa.selenium.remote.HttpCommandExecutor.execute(HttpCommandExecutor.java:162)
at org.openqa.selenium.remote.TracedCommandExecutor.execute(TracedCommandExecutor.java:53)
at org.openqa.selenium.remote.RemoteWebDriver.execute(RemoteWebDriver.java:545)
... 28 more
Caused by: java.util.concurrent.TimeoutException
at java.base/java.util.concurrent.CompletableFuture$Timeout.run(CompletableFuture.java:2920)
at java.base/java.util.concurrent.Executors$RunnableAdapter.call(Executors.java:572)
at java.base/java.util.concurrent.FutureTask.run(FutureTask.java:317)
at java.base/java.util.concurrent.ScheduledThreadPoolExecutor$ScheduledFutureTask.run(ScheduledThreadPoolExecutor.java:304)
at java.base/java.util.concurrent.ThreadPoolExecutor.runWorker(ThreadPoolExecutor.java:1144)
at java.base/java.util.concurrent.ThreadPoolExecutor$Worker.run(ThreadPoolExecutor.java:642)
at java.base/java.lang.Thread.run(Thread.java:1583)
]]>
    </error>
  </testcase> <!-- setup -->
</testsuite> <!-- testCases.TC_002_LoginTest -->
